const createHttpError = require('http-errors')
const { endpointResponse } = require('../helpers/success')
const { catchAsync } = require('../helpers/catchAsync')
const { getUsers, destroyUser } = require('../services/users')

module.exports = {
  get: catchAsync(async (req, res, next) => {
    try {
      const users = await getUsers()
      endpointResponse({
        res,
        message: 'Users list retrieved successfully',
        body: users,
      })
    } catch (error) {
      const httpError = createHttpError(
        error.statusCode,
        `[Error retrieving users list] - [users - GET]: ${error.message}`,
      )
      next(httpError)
    }
  }),
  destroy: catchAsync(async (req, res, next) => {
    try {
      const { id } = req.params
      const user = await destroyUser(id)
      endpointResponse({
        res,
        message: 'User deleted successfully',
        body: user,
      })
    } catch (error) {
      const httpError = createHttpError(
        error.statusCode,
        `[Error retrieving user delete] - [user - DELETE]: ${error.message}`,
      )
      next(httpError)
    }
  }),
}
